[30/Nov/2017 10:49:35] ERROR [login.services:26] Login Failure...wrong username/password
[30/Nov/2017 10:54:52] ERROR [login.services:55] Login success
[30/Nov/2017 10:54:52] ERROR [django.request:132] Internal Server Error: /user/login
Traceback (most recent call last):
  File "/usr/local/lib/python2.7/dist-packages/django/core/handlers/exception.py", line 42, in inner
    response = get_response(request)
  File "/usr/local/lib/python2.7/dist-packages/django/core/handlers/base.py", line 217, in _get_response
    response = self.process_exception_by_middleware(e, request)
  File "/usr/local/lib/python2.7/dist-packages/django/core/handlers/base.py", line 215, in _get_response
    response = response.render()
  File "/usr/local/lib/python2.7/dist-packages/django/template/response.py", line 109, in render
    self.content = self.rendered_content
  File "/usr/local/lib/python2.7/dist-packages/rest_framework/response.py", line 72, in rendered_content
    ret = renderer.render(self.data, accepted_media_type, context)
  File "/usr/local/lib/python2.7/dist-packages/rest_framework/renderers.py", line 105, in render
    separators=separators
  File "/usr/lib/python2.7/json/__init__.py", line 250, in dumps
    sort_keys=sort_keys, **kw).encode(obj)
  File "/usr/lib/python2.7/json/encoder.py", line 207, in encode
    chunks = self.iterencode(o, _one_shot=True)
  File "/usr/lib/python2.7/json/encoder.py", line 270, in iterencode
    return _iterencode(o, 0)
  File "/usr/local/lib/python2.7/dist-packages/rest_framework/utils/encoders.py", line 70, in default
    return super(JSONEncoder, self).default(obj)
  File "/usr/lib/python2.7/json/encoder.py", line 184, in default
    raise TypeError(repr(o) + " is not JSON serializable")
TypeError: listUserSerializer(<QuerySet [<Credentials: Credentials object>]>, many=True):
    name = CharField()
    id = IntegerField()
    email = EmailField() is not JSON serializable
[30/Nov/2017 10:54:52] ERROR [django.server:131] "POST /user/login HTTP/1.1" 500 93590
[30/Nov/2017 10:58:06] ERROR [login.services:55] Login success
[30/Nov/2017 11:00:57] ERROR [login.services:56] Login success
[30/Nov/2017 11:02:24] ERROR [django.request:132] Internal Server Error: /user/login
Traceback (most recent call last):
  File "/usr/local/lib/python2.7/dist-packages/django/core/handlers/exception.py", line 42, in inner
    response = get_response(request)
  File "/usr/local/lib/python2.7/dist-packages/django/core/handlers/base.py", line 217, in _get_response
    response = self.process_exception_by_middleware(e, request)
  File "/usr/local/lib/python2.7/dist-packages/django/core/handlers/base.py", line 215, in _get_response
    response = response.render()
  File "/usr/local/lib/python2.7/dist-packages/django/template/response.py", line 109, in render
    self.content = self.rendered_content
  File "/usr/local/lib/python2.7/dist-packages/rest_framework/response.py", line 72, in rendered_content
    ret = renderer.render(self.data, accepted_media_type, context)
  File "/usr/local/lib/python2.7/dist-packages/rest_framework/renderers.py", line 105, in render
    separators=separators
  File "/usr/lib/python2.7/json/__init__.py", line 250, in dumps
    sort_keys=sort_keys, **kw).encode(obj)
  File "/usr/lib/python2.7/json/encoder.py", line 207, in encode
    chunks = self.iterencode(o, _one_shot=True)
  File "/usr/lib/python2.7/json/encoder.py", line 270, in iterencode
    return _iterencode(o, 0)
  File "/usr/local/lib/python2.7/dist-packages/rest_framework/utils/encoders.py", line 70, in default
    return super(JSONEncoder, self).default(obj)
  File "/usr/lib/python2.7/json/encoder.py", line 184, in default
    raise TypeError(repr(o) + " is not JSON serializable")
TypeError: listUserSerializer(<QuerySet [<Credentials: Credentials object>]>, many=True):
    name = CharField()
    id = IntegerField()
    email = EmailField() is not JSON serializable
[30/Nov/2017 11:02:24] ERROR [django.server:131] "POST /user/login HTTP/1.1" 500 95177
[30/Nov/2017 11:02:39] ERROR [login.services:55] Login success
[30/Nov/2017 11:03:36] INFO [login.services:40] User successfully Deleted
[30/Nov/2017 11:03:40] INFO [login.services:40] User successfully Deleted
[30/Nov/2017 11:03:44] INFO [login.services:40] User successfully Deleted
[30/Nov/2017 11:03:47] ERROR [django.request:132] Internal Server Error: /user/delete
Traceback (most recent call last):
  File "/usr/local/lib/python2.7/dist-packages/django/core/handlers/exception.py", line 42, in inner
    response = get_response(request)
  File "/usr/local/lib/python2.7/dist-packages/django/core/handlers/base.py", line 187, in _get_response
    response = self.process_exception_by_middleware(e, request)
  File "/usr/local/lib/python2.7/dist-packages/django/core/handlers/base.py", line 185, in _get_response
    response = wrapped_callback(request, *callback_args, **callback_kwargs)
  File "/usr/local/lib/python2.7/dist-packages/django/views/decorators/csrf.py", line 58, in wrapped_view
    return view_func(*args, **kwargs)
  File "/usr/local/lib/python2.7/dist-packages/django/views/generic/base.py", line 68, in view
    return self.dispatch(request, *args, **kwargs)
  File "/usr/local/lib/python2.7/dist-packages/rest_framework/views.py", line 483, in dispatch
    response = self.handle_exception(exc)
  File "/usr/local/lib/python2.7/dist-packages/rest_framework/views.py", line 443, in handle_exception
    self.raise_uncaught_exception(exc)
  File "/usr/local/lib/python2.7/dist-packages/rest_framework/views.py", line 480, in dispatch
    response = handler(request, *args, **kwargs)
  File "/home/appadmin/myproject/login/views.py", line 28, in delete
    services.deleteUser(req_body)
  File "/home/appadmin/myproject/login/services.py", line 39, in deleteUser
    Credentials.objects.get(id=id).delete()
  File "/usr/local/lib/python2.7/dist-packages/django/db/models/manager.py", line 85, in manager_method
    return getattr(self.get_queryset(), name)(*args, **kwargs)
  File "/usr/local/lib/python2.7/dist-packages/django/db/models/query.py", line 385, in get
    self.model._meta.object_name
DoesNotExist: Credentials matching query does not exist.
[30/Nov/2017 11:03:47] ERROR [django.server:131] "DELETE /user/delete HTTP/1.1" 500 13610
[30/Nov/2017 11:03:51] INFO [login.services:40] User successfully Deleted
[30/Nov/2017 11:03:56] INFO [login.services:40] User successfully Deleted
[30/Nov/2017 11:03:59] INFO [login.services:40] User successfully Deleted
[30/Nov/2017 11:04:04] INFO [login.services:40] User successfully Deleted
[30/Nov/2017 11:04:15] INFO [login.services:40] User successfully Deleted
[30/Nov/2017 11:04:18] ERROR [django.request:132] Internal Server Error: /user/delete
Traceback (most recent call last):
  File "/usr/local/lib/python2.7/dist-packages/django/core/handlers/exception.py", line 42, in inner
    response = get_response(request)
  File "/usr/local/lib/python2.7/dist-packages/django/core/handlers/base.py", line 187, in _get_response
    response = self.process_exception_by_middleware(e, request)
  File "/usr/local/lib/python2.7/dist-packages/django/core/handlers/base.py", line 185, in _get_response
    response = wrapped_callback(request, *callback_args, **callback_kwargs)
  File "/usr/local/lib/python2.7/dist-packages/django/views/decorators/csrf.py", line 58, in wrapped_view
    return view_func(*args, **kwargs)
  File "/usr/local/lib/python2.7/dist-packages/django/views/generic/base.py", line 68, in view
    return self.dispatch(request, *args, **kwargs)
  File "/usr/local/lib/python2.7/dist-packages/rest_framework/views.py", line 483, in dispatch
    response = self.handle_exception(exc)
  File "/usr/local/lib/python2.7/dist-packages/rest_framework/views.py", line 443, in handle_exception
    self.raise_uncaught_exception(exc)
  File "/usr/local/lib/python2.7/dist-packages/rest_framework/views.py", line 480, in dispatch
    response = handler(request, *args, **kwargs)
  File "/home/appadmin/myproject/login/views.py", line 28, in delete
    services.deleteUser(req_body)
  File "/home/appadmin/myproject/login/services.py", line 39, in deleteUser
    Credentials.objects.get(id=id).delete()
  File "/usr/local/lib/python2.7/dist-packages/django/db/models/manager.py", line 85, in manager_method
    return getattr(self.get_queryset(), name)(*args, **kwargs)
  File "/usr/local/lib/python2.7/dist-packages/django/db/models/query.py", line 385, in get
    self.model._meta.object_name
DoesNotExist: Credentials matching query does not exist.
[30/Nov/2017 11:04:18] ERROR [django.server:131] "DELETE /user/delete HTTP/1.1" 500 13610
[30/Nov/2017 11:04:21] ERROR [django.request:132] Internal Server Error: /user/delete
Traceback (most recent call last):
  File "/usr/local/lib/python2.7/dist-packages/django/core/handlers/exception.py", line 42, in inner
    response = get_response(request)
  File "/usr/local/lib/python2.7/dist-packages/django/core/handlers/base.py", line 187, in _get_response
    response = self.process_exception_by_middleware(e, request)
  File "/usr/local/lib/python2.7/dist-packages/django/core/handlers/base.py", line 185, in _get_response
    response = wrapped_callback(request, *callback_args, **callback_kwargs)
  File "/usr/local/lib/python2.7/dist-packages/django/views/decorators/csrf.py", line 58, in wrapped_view
    return view_func(*args, **kwargs)
  File "/usr/local/lib/python2.7/dist-packages/django/views/generic/base.py", line 68, in view
    return self.dispatch(request, *args, **kwargs)
  File "/usr/local/lib/python2.7/dist-packages/rest_framework/views.py", line 483, in dispatch
    response = self.handle_exception(exc)
  File "/usr/local/lib/python2.7/dist-packages/rest_framework/views.py", line 443, in handle_exception
    self.raise_uncaught_exception(exc)
  File "/usr/local/lib/python2.7/dist-packages/rest_framework/views.py", line 480, in dispatch
    response = handler(request, *args, **kwargs)
  File "/home/appadmin/myproject/login/views.py", line 28, in delete
    services.deleteUser(req_body)
  File "/home/appadmin/myproject/login/services.py", line 39, in deleteUser
    Credentials.objects.get(id=id).delete()
  File "/usr/local/lib/python2.7/dist-packages/django/db/models/manager.py", line 85, in manager_method
    return getattr(self.get_queryset(), name)(*args, **kwargs)
  File "/usr/local/lib/python2.7/dist-packages/django/db/models/query.py", line 385, in get
    self.model._meta.object_name
DoesNotExist: Credentials matching query does not exist.
[30/Nov/2017 11:04:21] ERROR [django.server:131] "DELETE /user/delete HTTP/1.1" 500 13610
[30/Nov/2017 11:04:27] INFO [login.services:40] User successfully Deleted
[30/Nov/2017 11:04:38] INFO [login.services:40] User successfully Deleted
[30/Nov/2017 11:04:46] INFO [login.services:40] User successfully Deleted
[30/Nov/2017 11:50:04] INFO [login.services:17] New user navee is successfully created
[30/Nov/2017 11:50:33] INFO [login.services:17] New user test1 is successfully created
[30/Nov/2017 11:50:43] INFO [login.services:17] New user trial is successfully created
[30/Nov/2017 11:50:57] INFO [login.services:17] New user appadmin is successfully created
[30/Nov/2017 11:54:52] ERROR [login.services:55] Login success
[30/Nov/2017 11:57:07] ERROR [django.request:132] Internal Server Error: /user/list
Traceback (most recent call last):
  File "/usr/local/lib/python2.7/dist-packages/django/core/handlers/exception.py", line 42, in inner
    response = get_response(request)
  File "/usr/local/lib/python2.7/dist-packages/django/core/handlers/base.py", line 187, in _get_response
    response = self.process_exception_by_middleware(e, request)
  File "/usr/local/lib/python2.7/dist-packages/django/core/handlers/base.py", line 185, in _get_response
    response = wrapped_callback(request, *callback_args, **callback_kwargs)
  File "/usr/local/lib/python2.7/dist-packages/django/views/decorators/csrf.py", line 58, in wrapped_view
    return view_func(*args, **kwargs)
  File "/usr/local/lib/python2.7/dist-packages/django/views/generic/base.py", line 68, in view
    return self.dispatch(request, *args, **kwargs)
  File "/usr/local/lib/python2.7/dist-packages/rest_framework/views.py", line 483, in dispatch
    response = self.handle_exception(exc)
  File "/usr/local/lib/python2.7/dist-packages/rest_framework/views.py", line 443, in handle_exception
    self.raise_uncaught_exception(exc)
  File "/usr/local/lib/python2.7/dist-packages/rest_framework/views.py", line 480, in dispatch
    response = handler(request, *args, **kwargs)
  File "/home/appadmin/myproject/login/views.py", line 33, in get
    return Response(a, status=status.HTTP_201_CREATED)
NameError: global name 'status' is not defined
[30/Nov/2017 11:57:07] ERROR [django.server:131] "GET /user/list HTTP/1.1" 500 13171
[30/Nov/2017 12:05:36] ERROR [login.services:26] Login Success..
[30/Nov/2017 12:05:36] ERROR [login.services:34] Password reset for user navee
[30/Nov/2017 12:19:02] ERROR [django.request:132] Internal Server Error: /user/list
Traceback (most recent call last):
  File "/usr/local/lib/python2.7/dist-packages/django/core/handlers/exception.py", line 42, in inner
    response = get_response(request)
  File "/usr/local/lib/python2.7/dist-packages/django/core/handlers/base.py", line 217, in _get_response
    response = self.process_exception_by_middleware(e, request)
  File "/usr/local/lib/python2.7/dist-packages/django/core/handlers/base.py", line 215, in _get_response
    response = response.render()
  File "/usr/local/lib/python2.7/dist-packages/django/template/response.py", line 109, in render
    self.content = self.rendered_content
  File "/usr/local/lib/python2.7/dist-packages/rest_framework/response.py", line 72, in rendered_content
    ret = renderer.render(self.data, accepted_media_type, context)
  File "/usr/local/lib/python2.7/dist-packages/rest_framework/renderers.py", line 702, in render
    template = loader.get_template(self.template)
  File "/usr/local/lib/python2.7/dist-packages/django/template/loader.py", line 25, in get_template
    raise TemplateDoesNotExist(template_name, chain=chain)
TemplateDoesNotExist: rest_framework/api.html
[30/Nov/2017 12:19:03] ERROR [django.server:131] "GET /user/list HTTP/1.1" 500 78521
[30/Nov/2017 12:19:37] ERROR [django.request:132] Internal Server Error: /user/list
Traceback (most recent call last):
  File "/usr/local/lib/python2.7/dist-packages/django/core/handlers/exception.py", line 42, in inner
    response = get_response(request)
  File "/usr/local/lib/python2.7/dist-packages/django/core/handlers/base.py", line 217, in _get_response
    response = self.process_exception_by_middleware(e, request)
  File "/usr/local/lib/python2.7/dist-packages/django/core/handlers/base.py", line 215, in _get_response
    response = response.render()
  File "/usr/local/lib/python2.7/dist-packages/django/template/response.py", line 109, in render
    self.content = self.rendered_content
  File "/usr/local/lib/python2.7/dist-packages/rest_framework/response.py", line 72, in rendered_content
    ret = renderer.render(self.data, accepted_media_type, context)
  File "/usr/local/lib/python2.7/dist-packages/rest_framework/renderers.py", line 702, in render
    template = loader.get_template(self.template)
  File "/usr/local/lib/python2.7/dist-packages/django/template/loader.py", line 25, in get_template
    raise TemplateDoesNotExist(template_name, chain=chain)
TemplateDoesNotExist: rest_framework/api.html
[30/Nov/2017 12:19:37] ERROR [django.server:131] "GET /user/list HTTP/1.1" 500 78656
[30/Nov/2017 12:19:49] ERROR [django.request:132] Internal Server Error: /user/delete
Traceback (most recent call last):
  File "/usr/local/lib/python2.7/dist-packages/django/core/handlers/exception.py", line 42, in inner
    response = get_response(request)
  File "/usr/local/lib/python2.7/dist-packages/django/core/handlers/base.py", line 217, in _get_response
    response = self.process_exception_by_middleware(e, request)
  File "/usr/local/lib/python2.7/dist-packages/django/core/handlers/base.py", line 215, in _get_response
    response = response.render()
  File "/usr/local/lib/python2.7/dist-packages/django/template/response.py", line 109, in render
    self.content = self.rendered_content
  File "/usr/local/lib/python2.7/dist-packages/rest_framework/response.py", line 72, in rendered_content
    ret = renderer.render(self.data, accepted_media_type, context)
  File "/usr/local/lib/python2.7/dist-packages/rest_framework/renderers.py", line 702, in render
    template = loader.get_template(self.template)
  File "/usr/local/lib/python2.7/dist-packages/django/template/loader.py", line 25, in get_template
    raise TemplateDoesNotExist(template_name, chain=chain)
TemplateDoesNotExist: rest_framework/api.html
[30/Nov/2017 12:19:49] ERROR [django.server:131] "GET /user/delete HTTP/1.1" 500 78138
[30/Nov/2017 12:21:30] ERROR [django.request:132] Internal Server Error: /user/login
Traceback (most recent call last):
  File "/usr/local/lib/python2.7/dist-packages/django/core/handlers/exception.py", line 42, in inner
    response = get_response(request)
  File "/usr/local/lib/python2.7/dist-packages/django/core/handlers/base.py", line 187, in _get_response
    response = self.process_exception_by_middleware(e, request)
  File "/usr/local/lib/python2.7/dist-packages/django/core/handlers/base.py", line 185, in _get_response
    response = wrapped_callback(request, *callback_args, **callback_kwargs)
  File "/usr/local/lib/python2.7/dist-packages/django/views/decorators/csrf.py", line 58, in wrapped_view
    return view_func(*args, **kwargs)
  File "/usr/local/lib/python2.7/dist-packages/django/views/generic/base.py", line 68, in view
    return self.dispatch(request, *args, **kwargs)
  File "/usr/local/lib/python2.7/dist-packages/rest_framework/views.py", line 483, in dispatch
    response = self.handle_exception(exc)
  File "/usr/local/lib/python2.7/dist-packages/rest_framework/views.py", line 443, in handle_exception
    self.raise_uncaught_exception(exc)
  File "/usr/local/lib/python2.7/dist-packages/rest_framework/views.py", line 480, in dispatch
    response = handler(request, *args, **kwargs)
  File "/home/appadmin/myproject/login/views.py", line 37, in post
    req_str = json.loads(requests.body)
  File "/usr/lib/python2.7/json/__init__.py", line 338, in loads
    return _default_decoder.decode(s)
  File "/usr/lib/python2.7/json/decoder.py", line 366, in decode
    obj, end = self.raw_decode(s, idx=_w(s, 0).end())
  File "/usr/lib/python2.7/json/decoder.py", line 384, in raw_decode
    raise ValueError("No JSON object could be decoded")
ValueError: No JSON object could be decoded
[30/Nov/2017 12:21:30] ERROR [django.server:131] "POST /user/login HTTP/1.1" 500 14240
[30/Nov/2017 12:21:51] ERROR [django.request:132] Internal Server Error: /user/login
Traceback (most recent call last):
  File "/usr/local/lib/python2.7/dist-packages/django/core/handlers/exception.py", line 42, in inner
    response = get_response(request)
  File "/usr/local/lib/python2.7/dist-packages/django/core/handlers/base.py", line 187, in _get_response
    response = self.process_exception_by_middleware(e, request)
  File "/usr/local/lib/python2.7/dist-packages/django/core/handlers/base.py", line 185, in _get_response
    response = wrapped_callback(request, *callback_args, **callback_kwargs)
  File "/usr/local/lib/python2.7/dist-packages/django/views/decorators/csrf.py", line 58, in wrapped_view
    return view_func(*args, **kwargs)
  File "/usr/local/lib/python2.7/dist-packages/django/views/generic/base.py", line 68, in view
    return self.dispatch(request, *args, **kwargs)
  File "/usr/local/lib/python2.7/dist-packages/rest_framework/views.py", line 483, in dispatch
    response = self.handle_exception(exc)
  File "/usr/local/lib/python2.7/dist-packages/rest_framework/views.py", line 443, in handle_exception
    self.raise_uncaught_exception(exc)
  File "/usr/local/lib/python2.7/dist-packages/rest_framework/views.py", line 480, in dispatch
    response = handler(request, *args, **kwargs)
  File "/home/appadmin/myproject/login/views.py", line 37, in post
    req_str = json.loads(requests.body)
  File "/usr/lib/python2.7/json/__init__.py", line 338, in loads
    return _default_decoder.decode(s)
  File "/usr/lib/python2.7/json/decoder.py", line 366, in decode
    obj, end = self.raw_decode(s, idx=_w(s, 0).end())
  File "/usr/lib/python2.7/json/decoder.py", line 384, in raw_decode
    raise ValueError("No JSON object could be decoded")
ValueError: No JSON object could be decoded
[30/Nov/2017 12:21:51] ERROR [django.server:131] "POST /user/login HTTP/1.1" 500 14240
[30/Nov/2017 12:21:52] ERROR [django.request:132] Internal Server Error: /user/login
Traceback (most recent call last):
  File "/usr/local/lib/python2.7/dist-packages/django/core/handlers/exception.py", line 42, in inner
    response = get_response(request)
  File "/usr/local/lib/python2.7/dist-packages/django/core/handlers/base.py", line 187, in _get_response
    response = self.process_exception_by_middleware(e, request)
  File "/usr/local/lib/python2.7/dist-packages/django/core/handlers/base.py", line 185, in _get_response
    response = wrapped_callback(request, *callback_args, **callback_kwargs)
  File "/usr/local/lib/python2.7/dist-packages/django/views/decorators/csrf.py", line 58, in wrapped_view
    return view_func(*args, **kwargs)
  File "/usr/local/lib/python2.7/dist-packages/django/views/generic/base.py", line 68, in view
    return self.dispatch(request, *args, **kwargs)
  File "/usr/local/lib/python2.7/dist-packages/rest_framework/views.py", line 483, in dispatch
    response = self.handle_exception(exc)
  File "/usr/local/lib/python2.7/dist-packages/rest_framework/views.py", line 443, in handle_exception
    self.raise_uncaught_exception(exc)
  File "/usr/local/lib/python2.7/dist-packages/rest_framework/views.py", line 480, in dispatch
    response = handler(request, *args, **kwargs)
  File "/home/appadmin/myproject/login/views.py", line 37, in post
    req_str = json.loads(requests.body)
  File "/usr/lib/python2.7/json/__init__.py", line 338, in loads
    return _default_decoder.decode(s)
  File "/usr/lib/python2.7/json/decoder.py", line 366, in decode
    obj, end = self.raw_decode(s, idx=_w(s, 0).end())
  File "/usr/lib/python2.7/json/decoder.py", line 384, in raw_decode
    raise ValueError("No JSON object could be decoded")
ValueError: No JSON object could be decoded
[30/Nov/2017 12:21:52] ERROR [django.server:131] "POST /user/login HTTP/1.1" 500 14240
[30/Nov/2017 12:21:53] ERROR [django.request:132] Internal Server Error: /user/login
Traceback (most recent call last):
  File "/usr/local/lib/python2.7/dist-packages/django/core/handlers/exception.py", line 42, in inner
    response = get_response(request)
  File "/usr/local/lib/python2.7/dist-packages/django/core/handlers/base.py", line 187, in _get_response
    response = self.process_exception_by_middleware(e, request)
  File "/usr/local/lib/python2.7/dist-packages/django/core/handlers/base.py", line 185, in _get_response
    response = wrapped_callback(request, *callback_args, **callback_kwargs)
  File "/usr/local/lib/python2.7/dist-packages/django/views/decorators/csrf.py", line 58, in wrapped_view
    return view_func(*args, **kwargs)
  File "/usr/local/lib/python2.7/dist-packages/django/views/generic/base.py", line 68, in view
    return self.dispatch(request, *args, **kwargs)
  File "/usr/local/lib/python2.7/dist-packages/rest_framework/views.py", line 483, in dispatch
    response = self.handle_exception(exc)
  File "/usr/local/lib/python2.7/dist-packages/rest_framework/views.py", line 443, in handle_exception
    self.raise_uncaught_exception(exc)
  File "/usr/local/lib/python2.7/dist-packages/rest_framework/views.py", line 480, in dispatch
    response = handler(request, *args, **kwargs)
  File "/home/appadmin/myproject/login/views.py", line 37, in post
    req_str = json.loads(requests.body)
  File "/usr/lib/python2.7/json/__init__.py", line 338, in loads
    return _default_decoder.decode(s)
  File "/usr/lib/python2.7/json/decoder.py", line 366, in decode
    obj, end = self.raw_decode(s, idx=_w(s, 0).end())
  File "/usr/lib/python2.7/json/decoder.py", line 384, in raw_decode
    raise ValueError("No JSON object could be decoded")
ValueError: No JSON object could be decoded
[30/Nov/2017 12:21:53] ERROR [django.server:131] "POST /user/login HTTP/1.1" 500 14240
[30/Nov/2017 12:21:56] ERROR [django.request:132] Internal Server Error: /user/login
Traceback (most recent call last):
  File "/usr/local/lib/python2.7/dist-packages/django/core/handlers/exception.py", line 42, in inner
    response = get_response(request)
  File "/usr/local/lib/python2.7/dist-packages/django/core/handlers/base.py", line 187, in _get_response
    response = self.process_exception_by_middleware(e, request)
  File "/usr/local/lib/python2.7/dist-packages/django/core/handlers/base.py", line 185, in _get_response
    response = wrapped_callback(request, *callback_args, **callback_kwargs)
  File "/usr/local/lib/python2.7/dist-packages/django/views/decorators/csrf.py", line 58, in wrapped_view
    return view_func(*args, **kwargs)
  File "/usr/local/lib/python2.7/dist-packages/django/views/generic/base.py", line 68, in view
    return self.dispatch(request, *args, **kwargs)
  File "/usr/local/lib/python2.7/dist-packages/rest_framework/views.py", line 483, in dispatch
    response = self.handle_exception(exc)
  File "/usr/local/lib/python2.7/dist-packages/rest_framework/views.py", line 443, in handle_exception
    self.raise_uncaught_exception(exc)
  File "/usr/local/lib/python2.7/dist-packages/rest_framework/views.py", line 480, in dispatch
    response = handler(request, *args, **kwargs)
  File "/home/appadmin/myproject/login/views.py", line 37, in post
    req_str = json.loads(requests.body)
  File "/usr/lib/python2.7/json/__init__.py", line 338, in loads
    return _default_decoder.decode(s)
  File "/usr/lib/python2.7/json/decoder.py", line 366, in decode
    obj, end = self.raw_decode(s, idx=_w(s, 0).end())
  File "/usr/lib/python2.7/json/decoder.py", line 384, in raw_decode
    raise ValueError("No JSON object could be decoded")
ValueError: No JSON object could be decoded
[30/Nov/2017 12:21:56] ERROR [django.server:131] "POST /user/login HTTP/1.1" 500 14240
[30/Nov/2017 12:23:59] ERROR [django.request:132] Internal Server Error: /user/update
Traceback (most recent call last):
  File "/usr/local/lib/python2.7/dist-packages/django/core/handlers/exception.py", line 42, in inner
    response = get_response(request)
  File "/usr/local/lib/python2.7/dist-packages/django/core/handlers/base.py", line 187, in _get_response
    response = self.process_exception_by_middleware(e, request)
  File "/usr/local/lib/python2.7/dist-packages/django/core/handlers/base.py", line 185, in _get_response
    response = wrapped_callback(request, *callback_args, **callback_kwargs)
  File "/usr/local/lib/python2.7/dist-packages/django/views/decorators/csrf.py", line 58, in wrapped_view
    return view_func(*args, **kwargs)
  File "/usr/local/lib/python2.7/dist-packages/django/views/generic/base.py", line 68, in view
    return self.dispatch(request, *args, **kwargs)
  File "/usr/local/lib/python2.7/dist-packages/rest_framework/views.py", line 483, in dispatch
    response = self.handle_exception(exc)
  File "/usr/local/lib/python2.7/dist-packages/rest_framework/views.py", line 443, in handle_exception
    self.raise_uncaught_exception(exc)
  File "/usr/local/lib/python2.7/dist-packages/rest_framework/views.py", line 480, in dispatch
    response = handler(request, *args, **kwargs)
  File "/home/appadmin/myproject/login/views.py", line 20, in post
    req_body = json.loads(requests.body)
  File "/usr/lib/python2.7/json/__init__.py", line 338, in loads
    return _default_decoder.decode(s)
  File "/usr/lib/python2.7/json/decoder.py", line 366, in decode
    obj, end = self.raw_decode(s, idx=_w(s, 0).end())
  File "/usr/lib/python2.7/json/decoder.py", line 384, in raw_decode
    raise ValueError("No JSON object could be decoded")
ValueError: No JSON object could be decoded
[30/Nov/2017 12:23:59] ERROR [django.server:131] "POST /user/update HTTP/1.1" 500 14245
[30/Nov/2017 15:39:16] INFO [login.services:17] New user appadmindd is successfully created
[30/Nov/2017 15:44:05] INFO [login.services:17] New user appadmindd is successfully created
[30/Nov/2017 17:14:00] INFO [login.services:40] User successfully Deleted
[30/Nov/2017 17:14:04] INFO [login.services:40] User successfully Deleted
[30/Nov/2017 17:14:07] INFO [login.services:40] User successfully Deleted
[30/Nov/2017 17:14:09] INFO [login.services:40] User successfully Deleted
[30/Nov/2017 17:14:12] INFO [login.services:40] User successfully Deleted
[30/Nov/2017 17:14:22] INFO [login.services:40] User successfully Deleted
[30/Nov/2017 17:16:08] ERROR [django.request:132] Internal Server Error: /user/delete
Traceback (most recent call last):
  File "/usr/local/lib/python2.7/dist-packages/django/core/handlers/exception.py", line 42, in inner
    response = get_response(request)
  File "/usr/local/lib/python2.7/dist-packages/django/core/handlers/base.py", line 187, in _get_response
    response = self.process_exception_by_middleware(e, request)
  File "/usr/local/lib/python2.7/dist-packages/django/core/handlers/base.py", line 185, in _get_response
    response = wrapped_callback(request, *callback_args, **callback_kwargs)
  File "/usr/local/lib/python2.7/dist-packages/django/views/decorators/csrf.py", line 58, in wrapped_view
    return view_func(*args, **kwargs)
  File "/usr/local/lib/python2.7/dist-packages/django/views/generic/base.py", line 68, in view
    return self.dispatch(request, *args, **kwargs)
  File "/usr/local/lib/python2.7/dist-packages/rest_framework/views.py", line 483, in dispatch
    response = self.handle_exception(exc)
  File "/usr/local/lib/python2.7/dist-packages/rest_framework/views.py", line 443, in handle_exception
    self.raise_uncaught_exception(exc)
  File "/usr/local/lib/python2.7/dist-packages/rest_framework/views.py", line 480, in dispatch
    response = handler(request, *args, **kwargs)
  File "/home/appadmin/myproject/login/views.py", line 26, in delete
    req_body = json.loads(request.body)
  File "/usr/lib/python2.7/json/__init__.py", line 338, in loads
    return _default_decoder.decode(s)
  File "/usr/lib/python2.7/json/decoder.py", line 366, in decode
    obj, end = self.raw_decode(s, idx=_w(s, 0).end())
  File "/usr/lib/python2.7/json/decoder.py", line 384, in raw_decode
    raise ValueError("No JSON object could be decoded")
ValueError: No JSON object could be decoded
[30/Nov/2017 17:16:08] ERROR [django.server:131] "DELETE /user/delete HTTP/1.1" 500 14243
[30/Nov/2017 17:17:17] ERROR [django.request:132] Internal Server Error: /user/delete
Traceback (most recent call last):
  File "/usr/local/lib/python2.7/dist-packages/django/core/handlers/exception.py", line 42, in inner
    response = get_response(request)
  File "/usr/local/lib/python2.7/dist-packages/django/core/handlers/base.py", line 187, in _get_response
    response = self.process_exception_by_middleware(e, request)
  File "/usr/local/lib/python2.7/dist-packages/django/core/handlers/base.py", line 185, in _get_response
    response = wrapped_callback(request, *callback_args, **callback_kwargs)
  File "/usr/local/lib/python2.7/dist-packages/django/views/decorators/csrf.py", line 58, in wrapped_view
    return view_func(*args, **kwargs)
  File "/usr/local/lib/python2.7/dist-packages/django/views/generic/base.py", line 68, in view
    return self.dispatch(request, *args, **kwargs)
  File "/usr/local/lib/python2.7/dist-packages/rest_framework/views.py", line 483, in dispatch
    response = self.handle_exception(exc)
  File "/usr/local/lib/python2.7/dist-packages/rest_framework/views.py", line 443, in handle_exception
    self.raise_uncaught_exception(exc)
  File "/usr/local/lib/python2.7/dist-packages/rest_framework/views.py", line 480, in dispatch
    response = handler(request, *args, **kwargs)
  File "/home/appadmin/myproject/login/views.py", line 26, in delete
    req_body = json.loads(request.body)
  File "/usr/lib/python2.7/json/__init__.py", line 338, in loads
    return _default_decoder.decode(s)
  File "/usr/lib/python2.7/json/decoder.py", line 366, in decode
    obj, end = self.raw_decode(s, idx=_w(s, 0).end())
  File "/usr/lib/python2.7/json/decoder.py", line 384, in raw_decode
    raise ValueError("No JSON object could be decoded")
ValueError: No JSON object could be decoded
[30/Nov/2017 17:17:17] ERROR [django.server:131] "DELETE /user/delete HTTP/1.1" 500 14243
[30/Nov/2017 17:28:10] ERROR [django.request:132] Internal Server Error: /user/login
Traceback (most recent call last):
  File "/usr/local/lib/python2.7/dist-packages/django/core/handlers/exception.py", line 42, in inner
    response = get_response(request)
  File "/usr/local/lib/python2.7/dist-packages/django/core/handlers/base.py", line 187, in _get_response
    response = self.process_exception_by_middleware(e, request)
  File "/usr/local/lib/python2.7/dist-packages/django/core/handlers/base.py", line 185, in _get_response
    response = wrapped_callback(request, *callback_args, **callback_kwargs)
  File "/usr/local/lib/python2.7/dist-packages/django/views/decorators/csrf.py", line 58, in wrapped_view
    return view_func(*args, **kwargs)
  File "/usr/local/lib/python2.7/dist-packages/django/views/generic/base.py", line 68, in view
    return self.dispatch(request, *args, **kwargs)
  File "/usr/local/lib/python2.7/dist-packages/rest_framework/views.py", line 483, in dispatch
    response = self.handle_exception(exc)
  File "/usr/local/lib/python2.7/dist-packages/rest_framework/views.py", line 443, in handle_exception
    self.raise_uncaught_exception(exc)
  File "/usr/local/lib/python2.7/dist-packages/rest_framework/views.py", line 480, in dispatch
    response = handler(request, *args, **kwargs)
  File "/home/appadmin/myproject/login/views.py", line 37, in post
    req_str = json.loads(requests.body)
  File "/usr/lib/python2.7/json/__init__.py", line 338, in loads
    return _default_decoder.decode(s)
  File "/usr/lib/python2.7/json/decoder.py", line 366, in decode
    obj, end = self.raw_decode(s, idx=_w(s, 0).end())
  File "/usr/lib/python2.7/json/decoder.py", line 384, in raw_decode
    raise ValueError("No JSON object could be decoded")
ValueError: No JSON object could be decoded
[30/Nov/2017 17:28:10] ERROR [django.server:131] "POST /user/login HTTP/1.1" 500 14240
